command 'python C:\Users\z3531278\Documents\01_FEWS-RegionHome-Aus\Modules\PostProcessXBeach\postprocessMain.py C:\Users\z3531278\Documents\01_FEWS-RegionHome-Aus\Modules\PostProcessXBeach 2020020800 C:\Users\z3531278\Documents\01_FEWS-RegionHome-Aus\ Narrabeen' return with error (code 1): b'Traceback (most recent call last):\r\n  File "C:\\Users\\z3531278\\Documents\\01_FEWS-RegionHome-Aus\\bin\\windows\\python\\bin\\conda-venv\\lib\\distutils\\file_util.py", line 35, in _copy_file_contents\r\n    os.unlink(dst)\r\nPermissionError: [WinError 32] The process cannot access the file because it is being used by another process: \'C:\\\\Users\\\\z3531278\\\\Documents\\\\01_FEWS-RegionHome-Aus\\\\Forecasts\\\\20200208_0000\\\\NSW\\\\hotspot\\\\Narrabeen\\\\XBeach\\\\postProcess\\\\ewl_XBeach.dbf\'\r\n\r\nDuring handling of the above exception, another exception occurred:\r\n\r\nTraceback (most recent call last):\r\n  File "C:\\Users\\z3531278\\Documents\\01_FEWS-RegionHome-Aus\\Modules\\PostProcessXBeach\\postprocessMain.py", line 316, in <module>\r\n    main()\r\n  File "C:\\Users\\z3531278\\Documents\\01_FEWS-RegionHome-Aus\\Modules\\PostProcessXBeach\\postprocessMain.py", line 64, in main\r\n    copy_tree(fcstHotspot.moduleDir,fcstHotspot.xbWorkDir)\r\n  File "C:\\Users\\z3531278\\Documents\\01_FEWS-RegionHome-Aus\\bin\\windows\\python\\bin\\conda-venv\\lib\\distutils\\dir_util.py", line 157, in copy_tree\r\n    copy_tree(src_name, dst_name, preserve_mode,\r\n  File "C:\\Users\\z3531278\\Documents\\01_FEWS-RegionHome-Aus\\bin\\windows\\python\\bin\\conda-venv\\lib\\distutils\\dir_util.py", line 161, in copy_tree\r\n    copy_file(src_name, dst_name, preserve_mode,\r\n  File "C:\\Users\\z3531278\\Documents\\01_FEWS-RegionHome-Aus\\bin\\windows\\python\\bin\\conda-venv\\lib\\distutils\\file_util.py", line 151, in copy_file\r\n    _copy_file_contents(src, dst)\r\n  File "C:\\Users\\z3531278\\Documents\\01_FEWS-RegionHome-Aus\\bin\\windows\\python\\bin\\conda-venv\\lib\\distutils\\file_util.py", line 37, in _copy_file_contents\r\n    raise DistutilsFileError(\r\ndistutils.errors.DistutilsFileError: could not delete \'C:\\Users\\z3531278\\Documents\\01_FEWS-RegionHome-Aus\\Forecasts\\20200208_0000\\NSW\\hotspot\\Narrabeen\\XBeach\\postProcess\\ewl_XBeach.dbf\': The process cannot access the file because it is being used by another process\r\n'Traceback (most recent call last):
  File "C:\Users\z3531278\Documents\01_FEWS-RegionHome-Aus\Scripts\runForecast\run_forecast_loop.py", line 72, in runModule
    subprocess.check_output(command,shell=True,stderr=subprocess.STDOUT)
  File "C:\Users\z3531278\Documents\01_FEWS-RegionHome-Aus\bin\windows\python\bin\conda-venv\lib\subprocess.py", line 424, in check_output
    return run(*popenargs, stdout=PIPE, timeout=timeout, check=True,
  File "C:\Users\z3531278\Documents\01_FEWS-RegionHome-Aus\bin\windows\python\bin\conda-venv\lib\subprocess.py", line 528, in run
    raise CalledProcessError(retcode, process.args,
subprocess.CalledProcessError: Command 'python C:\Users\z3531278\Documents\01_FEWS-RegionHome-Aus\Modules\PostProcessXBeach\postprocessMain.py C:\Users\z3531278\Documents\01_FEWS-RegionHome-Aus\Modules\PostProcessXBeach 2020020800 C:\Users\z3531278\Documents\01_FEWS-RegionHome-Aus\ Narrabeen' returned non-zero exit status 1.

During handling of the above exception, another exception occurred:

Traceback (most recent call last):
  File "C:\Users\z3531278\Documents\01_FEWS-RegionHome-Aus\Scripts\runForecast\run_forecast_loop.py", line 242, in <module>
    main()
  File "C:\Users\z3531278\Documents\01_FEWS-RegionHome-Aus\Scripts\runForecast\run_forecast_loop.py", line 213, in main
    runModule(script=postProcessXBeachPy,args=arguments)
  File "C:\Users\z3531278\Documents\01_FEWS-RegionHome-Aus\Scripts\runForecast\run_forecast_loop.py", line 78, in runModule
    raise RuntimeError("command '{}' return with error (code {}): {}".format(e.cmd, e.returncode, e.output))
RuntimeError: command 'python C:\Users\z3531278\Documents\01_FEWS-RegionHome-Aus\Modules\PostProcessXBeach\postprocessMain.py C:\Users\z3531278\Documents\01_FEWS-RegionHome-Aus\Modules\PostProcessXBeach 2020020800 C:\Users\z3531278\Documents\01_FEWS-RegionHome-Aus\ Narrabeen' return with error (code 1): b'Traceback (most recent call last):\r\n  File "C:\\Users\\z3531278\\Documents\\01_FEWS-RegionHome-Aus\\bin\\windows\\python\\bin\\conda-venv\\lib\\distutils\\file_util.py", line 35, in _copy_file_contents\r\n    os.unlink(dst)\r\nPermissionError: [WinError 32] The process cannot access the file because it is being used by another process: \'C:\\\\Users\\\\z3531278\\\\Documents\\\\01_FEWS-RegionHome-Aus\\\\Forecasts\\\\20200208_0000\\\\NSW\\\\hotspot\\\\Narrabeen\\\\XBeach\\\\postProcess\\\\ewl_XBeach.dbf\'\r\n\r\nDuring handling of the above exception, another exception occurred:\r\n\r\nTraceback (most recent call last):\r\n  File "C:\\Users\\z3531278\\Documents\\01_FEWS-RegionHome-Aus\\Modules\\PostProcessXBeach\\postprocessMain.py", line 316, in <module>\r\n    main()\r\n  File "C:\\Users\\z3531278\\Documents\\01_FEWS-RegionHome-Aus\\Modules\\PostProcessXBeach\\postprocessMain.py", line 64, in main\r\n    copy_tree(fcstHotspot.moduleDir,fcstHotspot.xbWorkDir)\r\n  File "C:\\Users\\z3531278\\Documents\\01_FEWS-RegionHome-Aus\\bin\\windows\\python\\bin\\conda-venv\\lib\\distutils\\dir_util.py", line 157, in copy_tree\r\n    copy_tree(src_name, dst_name, preserve_mode,\r\n  File "C:\\Users\\z3531278\\Documents\\01_FEWS-RegionHome-Aus\\bin\\windows\\python\\bin\\conda-venv\\lib\\distutils\\dir_util.py", line 161, in copy_tree\r\n    copy_file(src_name, dst_name, preserve_mode,\r\n  File "C:\\Users\\z3531278\\Documents\\01_FEWS-RegionHome-Aus\\bin\\windows\\python\\bin\\conda-venv\\lib\\distutils\\file_util.py", line 151, in copy_file\r\n    _copy_file_contents(src, dst)\r\n  File "C:\\Users\\z3531278\\Documents\\01_FEWS-RegionHome-Aus\\bin\\windows\\python\\bin\\conda-venv\\lib\\distutils\\file_util.py", line 37, in _copy_file_contents\r\n    raise DistutilsFileError(\r\ndistutils.errors.DistutilsFileError: could not delete \'C:\\Users\\z3531278\\Documents\\01_FEWS-RegionHome-Aus\\Forecasts\\20200208_0000\\NSW\\hotspot\\Narrabeen\\XBeach\\postProcess\\ewl_XBeach.dbf\': The process cannot access the file because it is being used by another process\r\n'
