command 'python C:\Users\z3531278\Documents\01_FEWS-RegionHome-Aus\Modules\WipeForecast\wipeForecast.py C:\Users\z3531278\Documents\01_FEWS-RegionHome-Aus\Modules\WipeForecast 20200207_0000 C:\Users\z3531278\Documents\01_FEWS-RegionHome-Aus\ Narrabeen' return with error (code 1): NoneTraceback (most recent call last):
  File "C:\Users\z3531278\Documents\01_FEWS-RegionHome-Aus\Scripts\runForecast\run_forecast_loop.py", line 73, in runModule
    subprocess.run(command, check=True, shell=True)
  File "C:\Users\z3531278\Documents\01_FEWS-RegionHome-Aus\bin\windows\python\bin\conda-venv\lib\subprocess.py", line 438, in run
    output=stdout, stderr=stderr)
subprocess.CalledProcessError: Command 'python C:\Users\z3531278\Documents\01_FEWS-RegionHome-Aus\Modules\WipeForecast\wipeForecast.py C:\Users\z3531278\Documents\01_FEWS-RegionHome-Aus\Modules\WipeForecast 20200207_0000 C:\Users\z3531278\Documents\01_FEWS-RegionHome-Aus\ Narrabeen' returned non-zero exit status 1.

During handling of the above exception, another exception occurred:

Traceback (most recent call last):
  File "C:\Users\z3531278\Documents\01_FEWS-RegionHome-Aus\Scripts\runForecast\run_forecast_loop.py", line 240, in <module>
    main()
  File "C:\Users\z3531278\Documents\01_FEWS-RegionHome-Aus\Scripts\runForecast\run_forecast_loop.py", line 229, in main
    runModule(script=wipeForecastPy,args=arguments)
  File "C:\Users\z3531278\Documents\01_FEWS-RegionHome-Aus\Scripts\runForecast\run_forecast_loop.py", line 78, in runModule
    raise RuntimeError("command '{}' return with error (code {}): {}".format(e.cmd, e.returncode, e.output))
RuntimeError: command 'python C:\Users\z3531278\Documents\01_FEWS-RegionHome-Aus\Modules\WipeForecast\wipeForecast.py C:\Users\z3531278\Documents\01_FEWS-RegionHome-Aus\Modules\WipeForecast 20200207_0000 C:\Users\z3531278\Documents\01_FEWS-RegionHome-Aus\ Narrabeen' return with error (code 1): None
