command 'python C:\Users\z3531278\Documents\01_FEWS-RegionHome-Aus\Modules\IndicatorsXBeach\indicatorsMain.py C:\Users\z3531278\Documents\01_FEWS-RegionHome-Aus\ 20210910_0000 Narrabeen C:\Users\z3531278\Documents\01_FEWS-RegionHome-Aus\Modules\IndicatorsXBeach' return with error (code 1): b'35\r\n46\r\nTraceback (most recent call last):\r\n  File "C:\\Users\\z3531278\\Documents\\01_FEWS-RegionHome-Aus\\Modules\\IndicatorsXBeach\\indicatorsMain.py", line 191, in <module>\r\n    main()\r\n  File "C:\\Users\\z3531278\\Documents\\01_FEWS-RegionHome-Aus\\Modules\\IndicatorsXBeach\\indicatorsMain.py", line 113, in main\r\n    raise ValueError("Corridors shapefile does not have the same number of rows used in the XBeach model.")\r\nValueError: Corridors shapefile does not have the same number of rows used in the XBeach model.\r\n'Traceback (most recent call last):
  File "C:\Users\z3531278\Documents\01_FEWS-RegionHome-Aus\Scripts\runForecast\run_forecast_loop.py", line 70, in runModule
    subprocess.check_output(command,shell=True,stderr=subprocess.STDOUT)
  File "C:\Users\z3531278\Documents\01_FEWS-RegionHome-Aus\bin\windows\python\bin\conda-venv\lib\subprocess.py", line 415, in check_output
    return run(*popenargs, stdout=PIPE, timeout=timeout, check=True,
  File "C:\Users\z3531278\Documents\01_FEWS-RegionHome-Aus\bin\windows\python\bin\conda-venv\lib\subprocess.py", line 516, in run
    raise CalledProcessError(retcode, process.args,
subprocess.CalledProcessError: Command 'python C:\Users\z3531278\Documents\01_FEWS-RegionHome-Aus\Modules\IndicatorsXBeach\indicatorsMain.py C:\Users\z3531278\Documents\01_FEWS-RegionHome-Aus\ 20210910_0000 Narrabeen C:\Users\z3531278\Documents\01_FEWS-RegionHome-Aus\Modules\IndicatorsXBeach' returned non-zero exit status 1.

During handling of the above exception, another exception occurred:

Traceback (most recent call last):
  File "C:\Users\z3531278\Documents\01_FEWS-RegionHome-Aus\Scripts\runForecast\run_forecast_loop.py", line 238, in <module>
    main()
  File "C:\Users\z3531278\Documents\01_FEWS-RegionHome-Aus\Scripts\runForecast\run_forecast_loop.py", line 219, in main
    runModule(script=indicatorsXBeachPy,args=arguments)
  File "C:\Users\z3531278\Documents\01_FEWS-RegionHome-Aus\Scripts\runForecast\run_forecast_loop.py", line 76, in runModule
    raise RuntimeError("command '{}' return with error (code {}): {}".format(e.cmd, e.returncode, e.output))
RuntimeError: command 'python C:\Users\z3531278\Documents\01_FEWS-RegionHome-Aus\Modules\IndicatorsXBeach\indicatorsMain.py C:\Users\z3531278\Documents\01_FEWS-RegionHome-Aus\ 20210910_0000 Narrabeen C:\Users\z3531278\Documents\01_FEWS-RegionHome-Aus\Modules\IndicatorsXBeach' return with error (code 1): b'35\r\n46\r\nTraceback (most recent call last):\r\n  File "C:\\Users\\z3531278\\Documents\\01_FEWS-RegionHome-Aus\\Modules\\IndicatorsXBeach\\indicatorsMain.py", line 191, in <module>\r\n    main()\r\n  File "C:\\Users\\z3531278\\Documents\\01_FEWS-RegionHome-Aus\\Modules\\IndicatorsXBeach\\indicatorsMain.py", line 113, in main\r\n    raise ValueError("Corridors shapefile does not have the same number of rows used in the XBeach model.")\r\nValueError: Corridors shapefile does not have the same number of rows used in the XBeach model.\r\n'
