command 'python C:\Users\mandiruns\Documents\01_FEWS-RegionHome-Aus\Modules\IndicatorsXBeach\indicatorsMain.py C:\Users\mandiruns\Documents\01_FEWS-RegionHome-Aus\ 20200617_0000 Narrabeen C:\Users\mandiruns\Documents\01_FEWS-RegionHome-Aus\Modules\IndicatorsXBeach' return with error (code 1): NoneTraceback (most recent call last):
  File "C:\Users\mandiruns\Documents\01_FEWS-RegionHome-Aus\Scripts\runForecast\run_forecast_loop.py", line 110, in runModule
    subprocess.run(command, check=True, shell=True)
  File "C:\Users\mandiruns\Documents\01_FEWS-RegionHome-Aus\bin\windows\python\bin\conda-venv\lib\subprocess.py", line 516, in run
    raise CalledProcessError(retcode, process.args,
subprocess.CalledProcessError: Command 'python C:\Users\mandiruns\Documents\01_FEWS-RegionHome-Aus\Modules\IndicatorsXBeach\indicatorsMain.py C:\Users\mandiruns\Documents\01_FEWS-RegionHome-Aus\ 20200617_0000 Narrabeen C:\Users\mandiruns\Documents\01_FEWS-RegionHome-Aus\Modules\IndicatorsXBeach' returned non-zero exit status 1.

During handling of the above exception, another exception occurred:

Traceback (most recent call last):
  File "C:\Users\mandiruns\Documents\01_FEWS-RegionHome-Aus\Scripts\runForecast\run_forecast_loop.py", line 311, in <module>
    main()
  File "C:\Users\mandiruns\Documents\01_FEWS-RegionHome-Aus\Scripts\runForecast\run_forecast_loop.py", line 294, in main
    runModule(script=indicatorsXBeachPy,args=arguments)
  File "C:\Users\mandiruns\Documents\01_FEWS-RegionHome-Aus\Scripts\runForecast\run_forecast_loop.py", line 114, in runModule
    raise RuntimeError("command '{}' return with error (code {}): {}".format(e.cmd, e.returncode, e.output))
RuntimeError: command 'python C:\Users\mandiruns\Documents\01_FEWS-RegionHome-Aus\Modules\IndicatorsXBeach\indicatorsMain.py C:\Users\mandiruns\Documents\01_FEWS-RegionHome-Aus\ 20200617_0000 Narrabeen C:\Users\mandiruns\Documents\01_FEWS-RegionHome-Aus\Modules\IndicatorsXBeach' return with error (code 1): None
