command 'python C:\Users\z3531278\Documents\01_FEWS-RegionHome-Aus\Modules\PreProcessXBeach\preprocessMain.py C:\Users\z3531278\Documents\01_FEWS-RegionHome-Aus\Modules\PreProcessXBeach 20200208_0000 C:\Users\z3531278\Documents\01_FEWS-RegionHome-Aus\ Narrabeen' return with error (code 1): b'C:\\Users\\z3531278\\Documents\\01_FEWS-RegionHome-Aus\\bin\\windows\\python\\bin\\conda-venv\\lib\\site-packages\\xarray\\core\\indexes.py:91: FutureWarning: Indexing a timezone-naive DatetimeIndex with a timezone-aware datetime is deprecated and will raise KeyError in a future version.  Use a timezone-naive object instead.\r\n  indexer = index.slice_indexer(\r\n  storm_start           storm_end\r\n0  2020-02-08 2020-02-10 15:00:00\r\nTraceback (most recent call last):\r\n  File "C:\\Users\\z3531278\\Documents\\01_FEWS-RegionHome-Aus\\bin\\windows\\python\\bin\\conda-venv\\lib\\site-packages\\pandas\\core\\indexes\\range.py", line 385, in get_loc\r\n    return self._range.index(new_key)\r\nValueError: -1 is not in range\r\n\r\nThe above exception was the direct cause of the following exception:\r\n\r\nTraceback (most recent call last):\r\n  File "C:\\Users\\z3531278\\Documents\\01_FEWS-RegionHome-Aus\\Modules\\PreProcessXBeach\\preprocessMain.py", line 402, in <module>\r\n    main()\r\n  File "C:\\Users\\z3531278\\Documents\\01_FEWS-RegionHome-Aus\\Modules\\PreProcessXBeach\\preprocessMain.py", line 284, in main\r\n    stormEnd = hotspotFcst.stormPeriods[\'storm_end\'][-1].tz_localize(timezone.utc).to_pydatetime()\r\n  File "C:\\Users\\z3531278\\Documents\\01_FEWS-RegionHome-Aus\\bin\\windows\\python\\bin\\conda-venv\\lib\\site-packages\\pandas\\core\\series.py", line 942, in __getitem__\r\n    return self._get_value(key)\r\n  File "C:\\Users\\z3531278\\Documents\\01_FEWS-RegionHome-Aus\\bin\\windows\\python\\bin\\conda-venv\\lib\\site-packages\\pandas\\core\\series.py", line 1051, in _get_value\r\n    loc = self.index.get_loc(label)\r\n  File "C:\\Users\\z3531278\\Documents\\01_FEWS-RegionHome-Aus\\bin\\windows\\python\\bin\\conda-venv\\lib\\site-packages\\pandas\\core\\indexes\\range.py", line 387, in get_loc\r\n    raise KeyError(key) from err\r\nKeyError: -1\r\n'Traceback (most recent call last):
  File "C:\Users\z3531278\Documents\01_FEWS-RegionHome-Aus\Scripts\runForecast\run_forecast_loop.py", line 72, in runModule
    subprocess.check_output(command,shell=True,stderr=subprocess.STDOUT)
  File "C:\Users\z3531278\Documents\01_FEWS-RegionHome-Aus\bin\windows\python\bin\conda-venv\lib\subprocess.py", line 424, in check_output
    return run(*popenargs, stdout=PIPE, timeout=timeout, check=True,
  File "C:\Users\z3531278\Documents\01_FEWS-RegionHome-Aus\bin\windows\python\bin\conda-venv\lib\subprocess.py", line 528, in run
    raise CalledProcessError(retcode, process.args,
subprocess.CalledProcessError: Command 'python C:\Users\z3531278\Documents\01_FEWS-RegionHome-Aus\Modules\PreProcessXBeach\preprocessMain.py C:\Users\z3531278\Documents\01_FEWS-RegionHome-Aus\Modules\PreProcessXBeach 20200208_0000 C:\Users\z3531278\Documents\01_FEWS-RegionHome-Aus\ Narrabeen' returned non-zero exit status 1.

During handling of the above exception, another exception occurred:

Traceback (most recent call last):
  File "C:\Users\z3531278\Documents\01_FEWS-RegionHome-Aus\Scripts\runForecast\run_forecast_loop.py", line 242, in <module>
    main()
  File "C:\Users\z3531278\Documents\01_FEWS-RegionHome-Aus\Scripts\runForecast\run_forecast_loop.py", line 184, in main
    runModule(script=preProcessXBeachPy,args=arguments)
  File "C:\Users\z3531278\Documents\01_FEWS-RegionHome-Aus\Scripts\runForecast\run_forecast_loop.py", line 78, in runModule
    raise RuntimeError("command '{}' return with error (code {}): {}".format(e.cmd, e.returncode, e.output))
RuntimeError: command 'python C:\Users\z3531278\Documents\01_FEWS-RegionHome-Aus\Modules\PreProcessXBeach\preprocessMain.py C:\Users\z3531278\Documents\01_FEWS-RegionHome-Aus\Modules\PreProcessXBeach 20200208_0000 C:\Users\z3531278\Documents\01_FEWS-RegionHome-Aus\ Narrabeen' return with error (code 1): b'C:\\Users\\z3531278\\Documents\\01_FEWS-RegionHome-Aus\\bin\\windows\\python\\bin\\conda-venv\\lib\\site-packages\\xarray\\core\\indexes.py:91: FutureWarning: Indexing a timezone-naive DatetimeIndex with a timezone-aware datetime is deprecated and will raise KeyError in a future version.  Use a timezone-naive object instead.\r\n  indexer = index.slice_indexer(\r\n  storm_start           storm_end\r\n0  2020-02-08 2020-02-10 15:00:00\r\nTraceback (most recent call last):\r\n  File "C:\\Users\\z3531278\\Documents\\01_FEWS-RegionHome-Aus\\bin\\windows\\python\\bin\\conda-venv\\lib\\site-packages\\pandas\\core\\indexes\\range.py", line 385, in get_loc\r\n    return self._range.index(new_key)\r\nValueError: -1 is not in range\r\n\r\nThe above exception was the direct cause of the following exception:\r\n\r\nTraceback (most recent call last):\r\n  File "C:\\Users\\z3531278\\Documents\\01_FEWS-RegionHome-Aus\\Modules\\PreProcessXBeach\\preprocessMain.py", line 402, in <module>\r\n    main()\r\n  File "C:\\Users\\z3531278\\Documents\\01_FEWS-RegionHome-Aus\\Modules\\PreProcessXBeach\\preprocessMain.py", line 284, in main\r\n    stormEnd = hotspotFcst.stormPeriods[\'storm_end\'][-1].tz_localize(timezone.utc).to_pydatetime()\r\n  File "C:\\Users\\z3531278\\Documents\\01_FEWS-RegionHome-Aus\\bin\\windows\\python\\bin\\conda-venv\\lib\\site-packages\\pandas\\core\\series.py", line 942, in __getitem__\r\n    return self._get_value(key)\r\n  File "C:\\Users\\z3531278\\Documents\\01_FEWS-RegionHome-Aus\\bin\\windows\\python\\bin\\conda-venv\\lib\\site-packages\\pandas\\core\\series.py", line 1051, in _get_value\r\n    loc = self.index.get_loc(label)\r\n  File "C:\\Users\\z3531278\\Documents\\01_FEWS-RegionHome-Aus\\bin\\windows\\python\\bin\\conda-venv\\lib\\site-packages\\pandas\\core\\indexes\\range.py", line 387, in get_loc\r\n    raise KeyError(key) from err\r\nKeyError: -1\r\n'
